Workbook

Sheet Contry Selection
A1: Area | B1: Export value | C1: Import value | D1: Totale complessivo | E1: NET | F1: Percentual | G1: Type
A2: Australia | B2: 46126915 | C2: 17608824 | D2: 63735739 | E2: 28518091 | F2: 0.72372135 | G2: OECD
A3: Austria | B3: 18256072 | C3: 20105971 | D3: 38362042 | E3: -1849898.9 | F3: 0.47588894 | G3: OECD
A4: Belgium | B4: 62422217 | C4: 52131382 | D4: 1.145536e+08 | E4: 10290835 | F4: 0.54491712 | G4: OECD
A5: Brazil | B5: 1.4189479e+08 | C5: 14925007 | D5: 1.5681979e+08 | E5: 1.2696978e+08 | F5: 0.90482702 | G5: BRICS
A6: Canada | B6: 65303506 | C6: 46607782 | D6: 1.1191129e+08 | E6: 18695724 | F6: 0.58352922 | G6: OECD
A7: Chile | B7: 14633281 | C7: 9802327.5 | D7: 24435609 | E7: 4830953.5 | F7: 0.59885069 | G7: OECD
A8: China | B8: 84328729 | C8: 2.3269723e+08 | D8: 3.1702596e+08 | E8: -1.483685e+08 | F8: 0.26599944 | G8: BRICS
A9: Colombia | B9: 11281114 | C9: 8403599.8 | D9: 19684713 | E9: 2877513.7 | F9: 0.57309006 | G9: OECD
A10: Costa Rica | B10: 6466777.9 | C10: 3062035.9 | D10: 9528813.8 | E10: 3404742.1 | F10: 0.67865508 | G10: OECD
A11: Denmark | B11: 19263170 | C11: 13976002 | D11: 33239172 | E11: 5287168 | F11: 0.57953219 | G11: OECD
A12: Egypt | B12: 10013683 | C12: 18980653 | D12: 28994336 | E12: -8966969.9 | F12: 0.34536687 | G12: BRICS
A13: Estonia | B13: 1952218.4 | C13: 2623352.5 | D13: 4575570.9 | E13: -671134.11 | F13: 0.42666116 | G13: OECD
... A42: United States of America | B42: 172359214 | C42: 2.1236685e+08 | D42: 3.8472606e+08 | E42: -40007634 | F42: 0.44800504 | G42: OECD
A43: Saudi Arabia | B43: 5718807.7 | C43: 29523013 | D43: =SUM(B43:C43) -> 35241820 | E43: =B43-C43 -> -23804205 | F43: =B43/D43 -> 0.16227333 | G43: BRICS
A44: New Zealand | B44: 27005233 | C44: 5811156.5 | D44: =SUM(B44:C44) -> 32816390 | E44: =B44-C44 -> 21194077 | F44: =B44/D44 -> 0.82291908 | G44: OECD

Sheet PanelData
A1: area | B1: Year | C1: Type | D1: GDP_pc | E1: Emissions_CH4 | F1: Emissions_N2O | G1: Emissions_CO2 | H1: Agri_VA_pct | I1: Agri_Land_prc | J1: Cereal_Yield
A2: Australia | B2: 2000 | C2: OECD | D2: =INDEX(GDP_pc!$E:$ZZ, MATCH(A2, GDP_pc!$C:$C, 0), MATCH(B2, GDP_pc!$E$1:$ZZ$1, 0)) -> 4.1690196e+11 | E2: =INDEX(CH4_Em!$E:$ZZ, MATCH(A2, CH4_Em!$C:$C, 0), MATCH(B2, CH4_Em!$E$1:$ZZ$1, 0)) -> 88.5281 | F2: =INDEX(N2O_Em!$E:$ZZ, MATCH(A2, N2O_Em!$C:$C, 0), MATCH(B2, N2O_Em!$E$1:$ZZ$1, 0)) -> 34.8807 | G2: =INDEX(CO2_Em!$E:$ZZ, MATCH(A2, CO2_Em!$C:$C, 0), MATCH(B2, CO2_Em!$E$1:$ZZ$1, 0)) -> 1.253 | H2: =INDEX(Agri_VA!$E:$ZZ, MATCH(A2, Agri_VA!$C:$C, 0), MATCH(B2, Agri_VA!$E$1:$ZZ$1, 0)) -> 3.1063068 | I2: =INDEX('Agri_land '!$E:$ZZ, MATCH(A2, 'Agri_land '!$C:$C, 0), MATCH(B2, 'Agri_land '!$E$1:$ZZ$1, 0)) -> 59.288104 | J2: =INDEX(Cereal_Yield!$E:$ZZ, MATCH(A2, Cereal_Yield!$C:$C, 0), MATCH(B2, Cereal_Yield!$E$1:$ZZ$1, 0)) -> 2107.3
A3: Australia | B3: 2001 | C3: OECD | D3: =INDEX(GDP_pc!$E:$ZZ, MATCH(A3, GDP_pc!$C:$C, 0), MATCH(B3, GDP_pc!$E$1:$ZZ$1, 0)) -> 3.8036022e+11 | E3: =INDEX(CH4_Em!$E:$ZZ, MATCH(A3, CH4_Em!$C:$C, 0), MATCH(B3, CH4_Em!$E$1:$ZZ$1, 0)) -> 87.5876 | F3: =INDEX(N2O_Em!$E:$ZZ, MATCH(A3, N2O_Em!$C:$C, 0), MATCH(B3, N2O_Em!$E$1:$ZZ$1, 0)) -> 34.762 | G3: =INDEX(CO2_Em!$E:$ZZ, MATCH(A3, CO2_Em!$C:$C, 0), MATCH(B3, CO2_Em!$E$1:$ZZ$1, 0)) -> 1.3771 | H3: =INDEX(Agri_VA!$E:$ZZ, MATCH(A3, Agri_VA!$C:$C, 0), MATCH(B3, Agri_VA!$E$1:$ZZ$1, 0)) -> 3.5018709 | I3: =INDEX('Agri_land '!$E:$ZZ, MATCH(A3, 'Agri_land '!$C:$C, 0), MATCH(B3, 'Agri_land '!$E$1:$ZZ$1, 0)) -> 59.318173 | J3: =INDEX(Cereal_Yield!$E:$ZZ, MATCH(A3, Cereal_Yield!$C:$C, 0), MATCH(B3, Cereal_Yield!$E$1:$ZZ$1, 0)) -> 1959.6
A4: Australia | B4: 2002 | C4: OECD | D4: =INDEX(GDP_pc!$E:$ZZ, MATCH(A4, GDP_pc!$C:$C, 0), MATCH(B4, GDP_pc!$E$1:$ZZ$1, 0)) -> 3.9643697e+11 | E4: =INDEX(CH4_Em!$E:$ZZ, MATCH(A4, CH4_Em!$C:$C, 0), MATCH(B4, CH4_Em!$E$1:$ZZ$1, 0)) -> 86.8955 | F4: =INDEX(N2O_Em!$E:$ZZ, MATCH(A4, N2O_Em!$C:$C, 0), MATCH(B4, N2O_Em!$E$1:$ZZ$1, 0)) -> 34.4585 | G4: =INDEX(CO2_Em!$E:$ZZ, MATCH(A4, CO2_Em!$C:$C, 0), MATCH(B4, CO2_Em!$E$1:$ZZ$1, 0)) -> 1.6824 | H4: =INDEX(Agri_VA!$E:$ZZ, MATCH(A4, Agri_VA!$C:$C, 0), MATCH(B4, Agri_VA!$E$1:$ZZ$1, 0)) -> 3.9442512 | I4: =INDEX('Agri_land '!$E:$ZZ, MATCH(A4, 'Agri_land '!$C:$C, 0), MATCH(B4, 'Agri_land '!$E$1:$ZZ$1, 0)) -> 58.1857 | J4: =INDEX(Cereal_Yield!$E:$ZZ, MATCH(A4, Cereal_Yield!$C:$C, 0), MATCH(B4, Cereal_Yield!$E$1:$ZZ$1, 0)) -> 2197.5
A5: Australia | B5: 2003 | C5: OECD | D5: =INDEX(GDP_pc!$E:$ZZ, MATCH(A5, GDP_pc!$C:$C, 0), MATCH(B5, GDP_pc!$E$1:$ZZ$1, 0)) -> 4.6851718e+11 | E5: =INDEX(CH4_Em!$E:$ZZ, MATCH(A5, CH4_Em!$C:$C, 0), MATCH(B5, CH4_Em!$E$1:$ZZ$1, 0)) -> 82.2352 | F5: =INDEX(N2O_Em!$E:$ZZ, MATCH(A5, N2O_Em!$C:$C, 0), MATCH(B5, N2O_Em!$E$1:$ZZ$1, 0)) -> 31.846 | G5: =INDEX(CO2_Em!$E:$ZZ, MATCH(A5, CO2_Em!$C:$C, 0), MATCH(B5, CO2_Em!$E$1:$ZZ$1, 0)) -> 1.5745 | H5: =INDEX(Agri_VA!$E:$ZZ, MATCH(A5, Agri_VA!$C:$C, 0), MATCH(B5, Agri_VA!$E$1:$ZZ$1, 0)) -> 2.8873358 | I5: =INDEX('Agri_land '!$E:$ZZ, MATCH(A5, 'Agri_land '!$C:$C, 0), MATCH(B5, 'Agri_land '!$E$1:$ZZ$1, 0)) -> 57.209429 | J5: =INDEX(Cereal_Yield!$E:$ZZ, MATCH(A5, Cereal_Yield!$C:$C, 0), MATCH(B5, Cereal_Yield!$E$1:$ZZ$1, 0)) -> 1020.7
A6: Australia | B6: 2004 | C6: OECD | D6: =INDEX(GDP_pc!$E:$ZZ, MATCH(A6, GDP_pc!$C:$C, 0), MATCH(B6, GDP_pc!$E$1:$ZZ$1, 0)) -> 6.1564305e+11 | E6: =INDEX(CH4_Em!$E:$ZZ, MATCH(A6, CH4_Em!$C:$C, 0), MATCH(B6, CH4_Em!$E$1:$ZZ$1, 0)) -> 85.0559 | F6: =INDEX(N2O_Em!$E:$ZZ, MATCH(A6, N2O_Em!$C:$C, 0), MATCH(B6, N2O_Em!$E$1:$ZZ$1, 0)) -> 34.7715 | G6: =INDEX(CO2_Em!$E:$ZZ, MATCH(A6, CO2_Em!$C:$C, 0), MATCH(B6, CO2_Em!$E$1:$ZZ$1, 0)) -> 1.7662 | H6: =INDEX(Agri_VA!$E:$ZZ, MATCH(A6, Agri_VA!$C:$C, 0), MATCH(B6, Agri_VA!$E$1:$ZZ$1, 0)) -> 3.0582192 | I6: =INDEX('Agri_land '!$E:$ZZ, MATCH(A6, 'Agri_land '!$C:$C, 0), MATCH(B6, 'Agri_land '!$E$1:$ZZ$1, 0)) -> 51.404657 | J6: =INDEX(Cereal_Yield!$E:$ZZ, MATCH(A6, Cereal_Yield!$C:$C, 0), MATCH(B6, Cereal_Yield!$E$1:$ZZ$1, 0)) -> 2116.4
A7: Australia | B7: 2005 | C7: OECD | D7: =INDEX(GDP_pc!$E:$ZZ, MATCH(A7, GDP_pc!$C:$C, 0), MATCH(B7, GDP_pc!$E$1:$ZZ$1, 0)) -> 6.9681149e+11 | E7: =INDEX(CH4_Em!$E:$ZZ, MATCH(A7, CH4_Em!$C:$C, 0), MATCH(B7, CH4_Em!$E$1:$ZZ$1, 0)) -> 85.5892 | F7: =INDEX(N2O_Em!$E:$ZZ, MATCH(A7, N2O_Em!$C:$C, 0), MATCH(B7, N2O_Em!$E$1:$ZZ$1, 0)) -> 34.2219 | G7: =INDEX(CO2_Em!$E:$ZZ, MATCH(A7, CO2_Em!$C:$C, 0), MATCH(B7, CO2_Em!$E$1:$ZZ$1, 0)) -> 1.6164 | H7: =INDEX(Agri_VA!$E:$ZZ, MATCH(A7, Agri_VA!$C:$C, 0), MATCH(B7, Agri_VA!$E$1:$ZZ$1, 0)) -> 2.8892149 | I7: =INDEX('Agri_land '!$E:$ZZ, MATCH(A7, 'Agri_land '!$C:$C, 0), MATCH(B7, 'Agri_land '!$E$1:$ZZ$1, 0)) -> 53.399373 | J7: =INDEX(Cereal_Yield!$E:$ZZ, MATCH(A7, Cereal_Yield!$C:$C, 0), MATCH(B7, Cereal_Yield!$E$1:$ZZ$1, 0)) -> 1694.6
A8: Australia | B8: 2006 | C8: OECD | D8: =INDEX(GDP_pc!$E:$ZZ, MATCH(A8, GDP_pc!$C:$C, 0), MATCH(B8, GDP_pc!$E$1:$ZZ$1, 0)) -> 7.4970837e+11 | E8: =INDEX(CH4_Em!$E:$ZZ, MATCH(A8, CH4_Em!$C:$C, 0), MATCH(B8, CH4_Em!$E$1:$ZZ$1, 0)) -> 85.0017 | F8: =INDEX(N2O_Em!$E:$ZZ, MATCH(A8, N2O_Em!$C:$C, 0), MATCH(B8, N2O_Em!$E$1:$ZZ$1, 0)) -> 33.2678 | G8: =INDEX(CO2_Em!$E:$ZZ, MATCH(A8, CO2_Em!$C:$C, 0), MATCH(B8, CO2_Em!$E$1:$ZZ$1, 0)) -> 1.5009 | H8: =INDEX(Agri_VA!$E:$ZZ, MATCH(A8, Agri_VA!$C:$C, 0), MATCH(B8, Agri_VA!$E$1:$ZZ$1, 0)) -> 2.7401132 | I8: =INDEX('Agri_land '!$E:$ZZ, MATCH(A8, 'Agri_land '!$C:$C, 0), MATCH(B8, 'Agri_land '!$E$1:$ZZ$1, 0)) -> 53.278575 | J8: =INDEX(Cereal_Yield!$E:$ZZ, MATCH(A8, Cereal_Yield!$C:$C, 0), MATCH(B8, Cereal_Yield!$E$1:$ZZ$1, 0)) -> 2111.7
A9: Australia | B9: 2007 | C9: OECD | D9: =INDEX(GDP_pc!$E:$ZZ, MATCH(A9, GDP_pc!$C:$C, 0), MATCH(B9, GDP_pc!$E$1:$ZZ$1, 0)) -> 8.566036e+11 | E9: =INDEX(CH4_Em!$E:$ZZ, MATCH(A9, CH4_Em!$C:$C, 0), MATCH(B9, CH4_Em!$E$1:$ZZ$1, 0)) -> 82.57 | F9: =INDEX(N2O_Em!$E:$ZZ, MATCH(A9, N2O_Em!$C:$C, 0), MATCH(B9, N2O_Em!$E$1:$ZZ$1, 0)) -> 31.3726 | G9: =INDEX(CO2_Em!$E:$ZZ, MATCH(A9, CO2_Em!$C:$C, 0), MATCH(B9, CO2_Em!$E$1:$ZZ$1, 0)) -> 1.4408 | H9: =INDEX(Agri_VA!$E:$ZZ, MATCH(A9, Agri_VA!$C:$C, 0), MATCH(B9, Agri_VA!$E$1:$ZZ$1, 0)) -> 2.2128103 | I9: =INDEX('Agri_land '!$E:$ZZ, MATCH(A9, 'Agri_land '!$C:$C, 0), MATCH(B9, 'Agri_land '!$E$1:$ZZ$1, 0)) -> 51.853677 | J9: =INDEX(Cereal_Yield!$E:$ZZ, MATCH(A9, Cereal_Yield!$C:$C, 0), MATCH(B9, Cereal_Yield!$E$1:$ZZ$1, 0)) -> 981.3
A10: Australia | B10: 2008 | C10: OECD | D10: =INDEX(GDP_pc!$E:$ZZ, MATCH(A10, GDP_pc!$C:$C, 0), MATCH(B10, GDP_pc!$E$1:$ZZ$1, 0)) -> 1.0584482e+12 | E10: =INDEX(CH4_Em!$E:$ZZ, MATCH(A10, CH4_Em!$C:$C, 0), MATCH(B10, CH4_Em!$E$1:$ZZ$1, 0)) -> 78.6682 | F10: =INDEX(N2O_Em!$E:$ZZ, MATCH(A10, N2O_Em!$C:$C, 0), MATCH(B10, N2O_Em!$E$1:$ZZ$1, 0)) -> 30.3615 | G10: =INDEX(CO2_Em!$E:$ZZ, MATCH(A10, CO2_Em!$C:$C, 0), MATCH(B10, CO2_Em!$E$1:$ZZ$1, 0)) -> 1.4447 | H10: =INDEX(Agri_VA!$E:$ZZ, MATCH(A10, Agri_VA!$C:$C, 0), MATCH(B10, Agri_VA!$E$1:$ZZ$1, 0)) -> 2.3541791 | I10: =INDEX('Agri_land '!$E:$ZZ, MATCH(A10, 'Agri_land '!$C:$C, 0), MATCH(B10, 'Agri_land '!$E$1:$ZZ$1, 0)) -> 50.673366 | J10: =INDEX(Cereal_Yield!$E:$ZZ, MATCH(A10, Cereal_Yield!$C:$C, 0), MATCH(B10, Cereal_Yield!$E$1:$ZZ$1, 0)) -> 1332.7
A11: Australia | B11: 2009 | C11: OECD | D11: =INDEX(GDP_pc!$E:$ZZ, MATCH(A11, GDP_pc!$C:$C, 0), MATCH(B11, GDP_pc!$E$1:$ZZ$1, 0)) -> 9.3176169e+11 | E11: =INDEX(CH4_Em!$E:$ZZ, MATCH(A11, CH4_Em!$C:$C, 0), MATCH(B11, CH4_Em!$E$1:$ZZ$1, 0)) -> 79.3246 | F11: =INDEX(N2O_Em!$E:$ZZ, MATCH(A11, N2O_Em!$C:$C, 0), MATCH(B11, N2O_Em!$E$1:$ZZ$1, 0)) -> 30.8146 | G11: =INDEX(CO2_Em!$E:$ZZ, MATCH(A11, CO2_Em!$C:$C, 0), MATCH(B11, CO2_Em!$E$1:$ZZ$1, 0)) -> 1.4902 | H11: =INDEX(Agri_VA!$E:$ZZ, MATCH(A11, Agri_VA!$C:$C, 0), MATCH(B11, Agri_VA!$E$1:$ZZ$1, 0)) -> 2.3142357 | I11: =INDEX('Agri_land '!$E:$ZZ, MATCH(A11, 'Agri_land '!$C:$C, 0), MATCH(B11, 'Agri_land '!$E$1:$ZZ$1, 0)) -> 50.018484 | J11: =INDEX(Cereal_Yield!$E:$ZZ, MATCH(A11, Cereal_Yield!$C:$C, 0), MATCH(B11, Cereal_Yield!$E$1:$ZZ$1, 0)) -> 1651.4
A12: Australia | B12: 2010 | C12: OECD | D12: =INDEX(GDP_pc!$E:$ZZ, MATCH(A12, GDP_pc!$C:$C, 0), MATCH(B12, GDP_pc!$E$1:$ZZ$1, 0)) -> 1.1525666e+12 | E12: =INDEX(CH4_Em!$E:$ZZ, MATCH(A12, CH4_Em!$C:$C, 0), MATCH(B12, CH4_Em!$E$1:$ZZ$1, 0)) -> 75.9109 | F12: =INDEX(N2O_Em!$E:$ZZ, MATCH(A12, N2O_Em!$C:$C, 0), MATCH(B12, N2O_Em!$E$1:$ZZ$1, 0)) -> 30.5887 | G12: =INDEX(CO2_Em!$E:$ZZ, MATCH(A12, CO2_Em!$C:$C, 0), MATCH(B12, CO2_Em!$E$1:$ZZ$1, 0)) -> 1.6956 | H12: =INDEX(Agri_VA!$E:$ZZ, MATCH(A12, Agri_VA!$C:$C, 0), MATCH(B12, Agri_VA!$E$1:$ZZ$1, 0)) -> 2.2182484 | I12: =INDEX('Agri_land '!$E:$ZZ, MATCH(A12, 'Agri_land '!$C:$C, 0), MATCH(B12, 'Agri_land '!$E$1:$ZZ$1, 0)) -> 48.992099 | J12: =INDEX(Cereal_Yield!$E:$ZZ, MATCH(A12, Cereal_Yield!$C:$C, 0), MATCH(B12, Cereal_Yield!$E$1:$ZZ$1, 0)) -> 1661.5
A13: Australia | B13: 2011 | C13: OECD | D13: =INDEX(GDP_pc!$E:$ZZ, MATCH(A13, GDP_pc!$C:$C, 0), MATCH(B13, GDP_pc!$E$1:$ZZ$1, 0)) -> 1.4029399e+12 | E13: =INDEX(CH4_Em!$E:$ZZ, MATCH(A13, CH4_Em!$C:$C, 0), MATCH(B13, CH4_Em!$E$1:$ZZ$1, 0)) -> 81.325 | F13: =INDEX(N2O_Em!$E:$ZZ, MATCH(A13, N2O_Em!$C:$C, 0), MATCH(B13, N2O_Em!$E$1:$ZZ$1, 0)) -> 32.9616 | G13: =INDEX(CO2_Em!$E:$ZZ, MATCH(A13, CO2_Em!$C:$C, 0), MATCH(B13, CO2_Em!$E$1:$ZZ$1, 0)) -> 1.8323 | H13: =INDEX(Agri_VA!$E:$ZZ, MATCH(A13, Agri_VA!$C:$C, 0), MATCH(B13, Agri_VA!$E$1:$ZZ$1, 0)) -> 2.3048596 | I13: =INDEX('Agri_land '!$E:$ZZ, MATCH(A13, 'Agri_land '!$C:$C, 0), MATCH(B13, 'Agri_land '!$E$1:$ZZ$1, 0)) -> 51.562813 | J13: =INDEX(Cereal_Yield!$E:$ZZ, MATCH(A13, Cereal_Yield!$C:$C, 0), MATCH(B13, Cereal_Yield!$E$1:$ZZ$1, 0)) -> 2097.5
... A961: United States of America | B961: 2023 | C961: OECD | D961: =INDEX(GDP_pc!$E:$ZZ, MATCH(A961, GDP_pc!$C:$C, 0), MATCH(B961, GDP_pc!$E$1:$ZZ$1, 0)) -> 2.7292171e+13 | E961: =INDEX(CH4_Em!$E:$ZZ, MATCH(A961, CH4_Em!$C:$C, 0), MATCH(B961, CH4_Em!$E$1:$ZZ$1, 0)) -> 258.963 | F961: =INDEX(N2O_Em!$E:$ZZ, MATCH(A961, N2O_Em!$C:$C, 0), MATCH(B961, N2O_Em!$E$1:$ZZ$1, 0)) -> 137.6557 | G961: =INDEX(CO2_Em!$E:$ZZ, MATCH(A961, CO2_Em!$C:$C, 0), MATCH(B961, CO2_Em!$E$1:$ZZ$1, 0)) -> 6.804 | H961: =INDEX(Agri_VA!$E:$ZZ, MATCH(A961, Agri_VA!$C:$C, 0), MATCH(B961, Agri_VA!$E$1:$ZZ$1, 0)) -> .. | I961: =INDEX('Agri_land '!$E:$ZZ, MATCH(A961, 'Agri_land '!$C:$C, 0), MATCH(B961, 'Agri_land '!$E$1:$ZZ$1, 0)) -> 46.082979 | J961: =INDEX(Cereal_Yield!$E:$ZZ, MATCH(A961, Cereal_Yield!$C:$C, 0), MATCH(B961, Cereal_Yield!$E$1:$ZZ$1, 0)) -> 8329.7

Sheet GDP_pc
A1: Series Name | B1: Series Code | C1: Country Name | D1: Country Code | E1: 2000 | F1: 2001 | G1: 2002 | H1: 2003 | I1: 2004 | J1: 2005 | K1: 2006 | L1: 2007 | M1: 2008 | N1: 2009 | O1: 2010 | P1: 2011 | Q1: 2012 | R1: 2013 | S1: 2014 | T1: 2015 | U1: 2016 | V1: 2017 | W1: 2018 | X1: 2019 | Y1: 2020 | Z1: 2021 | AA1: 2022 | AB1: 2023
A2: GDP (current US$) | B2: NY.GDP.MKTP.CD | C2: Afghanistan | D2: AFG | E2: 3.5214181e+09 | F2: 2.8135718e+09 | G2: 3.8257014e+09 | H2: 4.5209468e+09 | I2: 5.2248967e+09 | J2: 6.2032565e+09 | K2: 6.9717583e+09 | L2: 9.7478862e+09 | M2: 1.0109297e+10 | N2: 1.2416153e+10 | O2: 1.5856669e+10 | P2: 1.7805098e+10 | Q2: 1.990733e+10 | R2: 2.0146417e+10 | S2: 2.0497129e+10 | T2: 1.9134222e+10 | U2: 1.8116572e+10 | V2: 1.8753456e+10 | W2: 1.8053223e+10 | X2: 1.8799444e+10 | Y2: 1.9955929e+10 | Z2: 1.4259995e+10 | AA2: 1.4497244e+10 | AB2: 1.7152235e+10
A3: GDP (current US$) | B3: NY.GDP.MKTP.CD | C3: Albania | D3: ALB | E3: 3.5845702e+09 | F3: 4.059064e+09 | G3: 4.5150031e+09 | H3: 5.801712e+09 | I3: 7.4066458e+09 | J3: 8.2566582e+09 | K3: 9.1505281e+09 | L3: 1.1116938e+10 | M3: 1.3258506e+10 | N3: 1.2335541e+10 | O3: 1.2086546e+10 | P3: 1.2973756e+10 | Q3: 1.22465e+10 | R3: 1.2796986e+10 | S3: 1.3296323e+10 | T3: 1.1470172e+10 | U3: 1.1988669e+10 | V3: 1.3258268e+10 | W3: 1.5379508e+10 | X3: 1.5585112e+10 | Y3: 1.5241459e+10 | Z3: 1.803199e+10 | AA3: 1.9017247e+10 | AB3: 2.3491243e+10
A4: GDP (current US$) | B4: NY.GDP.MKTP.CD | C4: Algeria | D4: DZA | E4: 5.4790399e+10 | F4: 5.9413401e+10 | G4: 6.1516103e+10 | H4: 7.3482264e+10 | I4: 9.1913681e+10 | J4: 1.0704662e+11 | K4: 1.2308426e+11 | L4: 1.4248274e+11 | M4: 1.8038385e+11 | N4: 1.5031729e+11 | O4: 1.7778505e+11 | P4: 2.1833195e+11 | Q4: 2.2714375e+11 | R4: 2.2970143e+11 | S4: 2.3894266e+11 | T4: 1.8749386e+11 | U4: 1.8076384e+11 | V4: 1.898809e+11 | W4: 1.9455448e+11 | X4: 1.9345966e+11 | Y4: 1.6487342e+11 | Z4: 1.8623121e+11 | AA4: 2.2558164e+11 | AB4: 2.4792389e+11
A5: GDP (current US$) | B5: NY.GDP.MKTP.CD | C5: American Samoa | D5: ASM | E5: .. | F5: .. | G5: 512000000 | H5: 524000000 | I5: 509000000 | J5: 500000000 | K5: 493000000 | L5: 518000000 | M5: 560000000 | N5: 675000000 | O5: 573000000 | P5: 570000000 | Q5: 640000000 | R5: 638000000 | S5: 643000000 | T5: 673000000 | U5: 671000000 | V5: 612000000 | W5: 639000000 | X5: 647000000 | Y5: 721000000 | Z5: 750000000 | AA5: 871000000 | AB5: ..
A6: GDP (current US$) | B6: NY.GDP.MKTP.CD | C6: Andorra | D6: AND | E6: 1.4326063e+09 | F6: 1.5482659e+09 | G6: 1.7642798e+09 | H6: 2.3669416e+09 | I6: 2.9002441e+09 | J6: 3.1610848e+09 | K6: 3.4593368e+09 | L6: 3.9576275e+09 | M6: 4.1023175e+09 | N6: 3.6889748e+09 | O6: 3.4499257e+09 | P6: 3.6291331e+09 | Q6: 3.1886533e+09 | R6: 3.1935135e+09 | S6: 3.2716865e+09 | T6: 2.7898826e+09 | U6: 2.8966119e+09 | V6: 3.0001604e+09 | W6: 3.2184186e+09 | X6: 3.1551503e+09 | Y6: 2.8910025e+09 | Z6: 3.3246481e+09 | AA6: 3.3806117e+09 | AB6: 3.7850655e+09
A7: GDP (current US$) | B7: NY.GDP.MKTP.CD | C7: Angola | D7: AGO | E7: 9.129595e+09 | F7: 8.9360791e+09 | G7: 1.7311512e+10 | H7: 2.0342128e+10 | I7: 2.6997978e+10 | J7: 4.1396636e+10 | K7: 5.865366e+10 | L7: 7.3037822e+10 | M7: 9.8790433e+10 | N7: 8.1705175e+10 | O7: 9.554692e+10 | P7: 1.2555163e+11 | Q7: 1.4357291e+11 | R7: 1.488452e+11 | S7: 1.5344986e+11 | T7: 1.0254307e+11 | U7: 5.987825e+10 | V7: 8.4376936e+10 | W7: 8.9512794e+10 | X7: 8.0734429e+10 | Y7: 5.8852456e+10 | Z7: 7.9559544e+10 | AA7: 1.3121221e+11 | AB7: 1.0716775e+11
A8: GDP (current US$) | B8: NY.GDP.MKTP.CD | C8: Antigua and Barbuda | D8: ATG | E8: 9.010037e+08 | F8: 8.7777407e+08 | G8: 8.9809259e+08 | H8: 9.481e+08 | I8: 1.0263296e+09 | J8: 1.1438963e+09 | K8: 1.3036741e+09 | L8: 1.4873815e+09 | M8: 1.5576407e+09 | N8: 1.3865185e+09 | O8: 1.2983481e+09 | P8: 1.2873593e+09 | Q8: 1.3647296e+09 | R8: 1.3254963e+09 | S8: 1.3787074e+09 | T8: 1.4374852e+09 | U8: 1.4896037e+09 | V8: 1.5348556e+09 | W8: 1.6615296e+09 | X8: 1.7264481e+09 | Y8: 1.411637e+09 | Z8: 1.6021259e+09 | AA8: 1.8665667e+09 | AB8: 2.0057852e+09
A9: GDP (current US$) | B9: NY.GDP.MKTP.CD | C9: Argentina | D9: ARG | E9: 284203750000 | F9: 268696750000 | G9: 9.7724004e+10 | H9: 1.2758697e+11 | I9: 1.6465793e+11 | J9: 1.987371e+11 | K9: 2.3255726e+11 | L9: 2.8753051e+11 | M9: 3.6155804e+11 | N9: 3.3297648e+11 | O9: 4.2362742e+11 | P9: 5.3015812e+11 | Q9: 5.4598238e+11 | R9: 5.5202514e+11 | S9: 5.2631967e+11 | T9: 5.9474929e+11 | U9: 5.5753232e+11 | V9: 6.4362839e+11 | W9: 5.2481989e+11 | X9: 4.4775468e+11 | Y9: 3.8574051e+11 | Z9: 4.8656409e+11 | AA9: 6.3399376e+11 | AB9: 6.4946169e+11
A10: GDP (current US$) | B10: NY.GDP.MKTP.CD | C10: Armenia | D10: ARM | E10: 1.9115637e+09 | F10: 2.1184679e+09 | G10: 2.376335e+09 | H10: 2.807061e+09 | I10: 3.5766152e+09 | J10: 4.9004695e+09 | K10: 6.3844521e+09 | L10: 9.2063013e+09 | M10: 1.1662041e+10 | N10: 8.6479371e+09 | O10: 9.2602858e+09 | P10: 1.0142112e+10 | Q10: 1.0619321e+10 | R10: 1.1121464e+10 | S10: 1.1609513e+10 | T10: 1.0553338e+10 | U10: 1.0546136e+10 | V10: 1.1527459e+10 | W10: 1.2457941e+10 | X10: 1.3619291e+10 | Y10: 1.2641699e+10 | Z10: 1.3878909e+10 | AA10: 1.9513507e+10 | AB10: 2.4185982e+10
A11: GDP (current US$) | B11: NY.GDP.MKTP.CD | C11: Aruba | D11: ABW | E11: 1.8734525e+09 | F11: 1.896457e+09 | G11: 1.9618436e+09 | H11: 2.0441117e+09 | I11: 2.2548307e+09 | J11: 2.3600173e+09 | K11: 2.4697827e+09 | L11: 2.6776413e+09 | M11: 2.8430246e+09 | N11: 2.5537933e+09 | O11: 2.4535972e+09 | P11: 2.6378592e+09 | Q11: 2.6152084e+09 | R11: 2.7278492e+09 | S11: 2.7908497e+09 | T11: 2.9629067e+09 | U11: 2.9836374e+09 | V11: 3.0924279e+09 | W11: 3.2761877e+09 | X11: 3.3466232e+09 | Y11: 2.4714192e+09 | Z11: 2.8809028e+09 | AA11: 3.3240344e+09 | AB11: 3.8347296e+09
A12: GDP (current US$) | B12: NY.GDP.MKTP.CD | C12: Australia | D12: AUS | E12: 4.1690196e+11 | F12: 3.8036022e+11 | G12: 3.9643697e+11 | H12: 4.6851718e+11 | I12: 6.1564305e+11 | J12: 6.9681149e+11 | K12: 7.4970837e+11 | L12: 8.566036e+11 | M12: 1.0584482e+12 | N12: 9.3176169e+11 | O12: 1.1525666e+12 | P12: 1.4029399e+12 | Q12: 1.5527284e+12 | R12: 1.5837375e+12 | S12: 1.474677e+12 | T12: 1.3568058e+12 | U12: 1.2115881e+12 | V12: 1.3308906e+12 | W12: 1.433145e+12 | X12: 1.3983496e+12 | Y12: 1.3333365e+12 | Z12: 1.5606175e+12 | AA12: 1.6956275e+12 | AB12: 1.7344513e+12
A13: GDP (current US$) | B13: NY.GDP.MKTP.CD | C13: Austria | D13: AUT | E13: 1.961816e+11 | F13: 1.9647721e+11 | G13: 2.1283722e+11 | H13: 2.6077983e+11 | I13: 2.9921041e+11 | J13: 3.1395232e+11 | K13: 3.3390598e+11 | L13: 3.8676018e+11 | M13: 4.292344e+11 | N13: 3.9929012e+11 | O13: 3.8982779e+11 | P13: 4.2895474e+11 | Q13: 4.0675049e+11 | R13: 4.265805e+11 | S13: 4.3855602e+11 | T13: 3.795461e+11 | U13: 3.9368736e+11 | V13: 4.1492614e+11 | W13: 4.5258229e+11 | X13: 4.4298364e+11 | Y13: 4.343976e+11 | Z13: 4.8046636e+11 | AA13: 4.732213e+11 | AB13: 5.1667051e+11
A14: GDP (current US$) | B14: NY.GDP.MKTP.CD | C14: Azerbaijan | D14: AZE | E14: 5.2726157e+09 | F14: 5.7076162e+09 | G14: 6.2360877e+09 | H14: 7.2764131e+09 | I14: 8.6804057e+09 | J14: 1.3245422e+10 | K14: 2.0981929e+10 | L14: 3.3049419e+10 | M14: 4.8851294e+10 | N14: 4.4292427e+10 | O14: 5.2909295e+10 | P14: 6.5952796e+10 | Q14: 6.9679945e+10 | R14: 7.416056e+10 | S14: 7.5239785e+10 | T14: 5.3076235e+10 | U14: 3.7866997e+10 | V14: 4.0866627e+10 | W14: 4.711247e+10 | X14: 4.8174235e+10 | Y14: 42693000000 | Z14: 5.4825412e+10 | AA14: 7.8807471e+10 | AB14: 7.2428471e+10
A15: GDP (current US$) | B15: NY.GDP.MKTP.CD | C15: Bahamas, The | D15: BHS | E15: 8076470000 | F15: 8317830000 | G15: 8881160000 | H15: 8870090000 | I15: 9055290000 | J15: 9836200000 | K15: 10167250000 | L15: 10618340000 | M15: 10526000000 | N15: 9981960000 | O15: 10095760000 | P15: 10070450000 | Q15: 10720400000 | R15: 10475300000 | S15: 11139100000 | T15: 11837600000 | U15: 11880900000 | V15: 12446900000 | W15: 12819200000 | X15: 13277000000 | Y15: 10363200000 | Z15: 12037000000 | AA15: 13896800000 | AB15: 15271300000
A16: GDP (current US$) | B16: NY.GDP.MKTP.CD | C16: Bahrain | D16: BHR | E16: 9.0628989e+09 | F16: 8.9761968e+09 | G16: 9.5935106e+09 | H16: 1.1074814e+10 | I16: 1.315016e+10 | J16: 1.5968723e+10 | K16: 1.8504761e+10 | L16: 21730000000 | M16: 2.5710904e+10 | N16: 2.2938218e+10 | O16: 2.6805984e+10 | P16: 2.9914681e+10 | Q16: 3.1963404e+10 | R16: 3.3823324e+10 | S16: 3.4772527e+10 | T16: 3.2523298e+10 | U16: 3.3884681e+10 | V16: 3.7204814e+10 | W16: 3.9567979e+10 | X16: 4.0446809e+10 | Y16: 3.5837633e+10 | Z16: 4.0840213e+10 | AA16: 4.6458191e+10 | AB16: 4.6192261e+10
A17: GDP (current US$) | B17: NY.GDP.MKTP.CD | C17: Bangladesh | D17: BGD | E17: 5.3369787e+10 | F17: 5.399129e+10 | G17: 5.4724081e+10 | H17: 6.0158929e+10 | I17: 6.5108544e+10 | J17: 6.9476001e+10 | K17: 7.1795736e+10 | L17: 7.9611645e+10 | M17: 9.1636997e+10 | N17: 1.0247516e+11 | O17: 1.1527554e+11 | P17: 1.2860748e+11 | Q17: 1.3331075e+11 | R17: 1.4999896e+11 | S17: 1.7288661e+11 | T17: 1.9514661e+11 | U17: 2.6522452e+11 | V17: 2.9373245e+11 | W17: 3.2136275e+11 | X17: 3.5123165e+11 | Y17: 3.7397944e+11 | Z17: 4.1627165e+11 | AA17: 4.6013169e+11 | AB17: 4.3741533e+11
... A28: GDP (current US$) | B28: NY.GDP.MKTP.CD | C28: Brazil | D28: BRA | E28: 6.5544819e+11 | F28: 5.599837e+11 | G28: 5.0979527e+11 | H28: 5.5823372e+11 | I28: 6.6928932e+11 | J28: 8.9163383e+11 | K28: 1.1076267e+12 | L28: 1.3971142e+12 | M28: 1.6958554e+12 | N28: 1.6669963e+12 | O28: 2.2088381e+12 | P28: 2.6161566e+12 | Q28: 2.4652283e+12 | R28: 2.4728194e+12 | S28: 2.4560438e+12 | T28: 1.802212e+12 | U28: 1.7956933e+12 | V28: 2.0635147e+12 | W28: 1.9169337e+12 | X28: 1.8732882e+12 | Y28: 1.4761073e+12 | Z28: 1.6706475e+12 | AA28: 1.9519238e+12 | AB28: 2.1911319e+12
A29: GDP (current US$) | B29: NY.GDP.MKTP.CD | C29: British Virgin Islands | D29: VGB | E29: .. | F29: .. | G29: .. | H29: .. | I29: .. | J29: .. | K29: .. | L29: .. | M29: .. | N29: .. | O29: .. | P29: .. | Q29: .. | R29: .. | S29: .. | T29: .. | U29: .. | V29: .. | W29: .. | X29: .. | Y29: .. | Z29: .. | AA29: .. | AB29: ..
A30: GDP (current US$) | B30: NY.GDP.MKTP.CD | C30: Brunei Darussalam | D30: BRN | E30: 6.5709991e+09 | F30: 6.0961558e+09 | G30: 6.3330829e+09 | H30: 7.1677253e+09 | I30: 8.6191788e+09 | J30: 1.0547203e+10 | K30: 1.2644616e+10 | L30: 1.3432029e+10 | M30: 1.5926457e+10 | N30: 1.1912905e+10 | O30: 1.3707121e+10 | P30: 1.8524791e+10 | Q30: 1.9048443e+10 | R30: 1.8094148e+10 | S30: 1.7097797e+10 | T30: 1.2930297e+10 | U30: 1.1400266e+10 | V30: 1.2128168e+10 | W30: 1.3566908e+10 | X30: 1.3469235e+10 | Y30: 1.20058e+10 | Z30: 1.4006497e+10 | AA30: 1.6681536e+10 | AB30: 1.5095085e+10
A31: GDP (current US$) | B31: NY.GDP.MKTP.CD | C31: Bulgaria | D31: BGR | E31: 1.324599e+10 | F31: 1.4183446e+10 | G31: 1.6403044e+10 | H31: 2.1144958e+10 | I31: 2.6157743e+10 | J31: 2.9868658e+10 | K31: 3.4380536e+10 | L31: 4.4431257e+10 | M31: 5.4480684e+10 | N31: 5.2023801e+10 | O31: 5.0689051e+10 | P31: 5.7681293e+10 | Q31: 5.4297052e+10 | R31: 5.5819262e+10 | S31: 5.7080897e+10 | T31: 5.0765918e+10 | U31: 5.3929397e+10 | V31: 5.9167647e+10 | W31: 6.6097226e+10 | X31: 6.8507731e+10 | Y31: 7.0486878e+10 | Z31: 8.4374613e+10 | AA31: 9.0506153e+10 | AB31: 1.0219923e+11
A32: GDP (current US$) | B32: NY.GDP.MKTP.CD | C32: Burkina Faso | D32: BFA | E32: 2.9683701e+09 | F32: 3.1903711e+09 | G32: 3.6223501e+09 | H32: 4.7407681e+09 | I32: 5.4516885e+09 | J32: 6.1463532e+09 | K32: 6.5474198e+09 | L32: 7.6257228e+09 | M32: 9.4514355e+09 | N32: 9.4506969e+09 | O32: 1.010962e+10 | P32: 1.2080296e+10 | Q32: 1.2561015e+10 | R32: 1.34443e+10 | S32: 1.3943016e+10 | T32: 1.1832159e+10 | U32: 1.2833363e+10 | V32: 1.4106956e+10 | W32: 1.5890066e+10 | X32: 1.6032814e+10 | Y32: 1.7725011e+10 | Z32: 1.9697516e+10 | AA32: 1.8622421e+10 | AB32: 2.0112614e+10
A33: GDP (current US$) | B33: NY.GDP.MKTP.CD | C33: Burundi | D33: BDI | E33: 8.7048607e+08 | F33: 8.7679472e+08 | G33: 8.2539452e+08 | H33: 7.8465442e+08 | I33: 9.1525732e+08 | J33: 1.1171131e+09 | K33: 1.2733751e+09 | L33: 1.3561994e+09 | M33: 1.6118359e+09 | N33: 1.775495e+09 | O33: 2.0321352e+09 | P33: 2.2358129e+09 | Q33: 2.3274024e+09 | R33: 2.4516246e+09 | S33: 2.7058266e+09 | T33: 2.8105329e+09 | U33: 2.6180931e+09 | V33: 2.8313622e+09 | W33: 2.9134114e+09 | X33: 2.8715553e+09 | Y33: 3.2278473e+09 | Z33: 3.4355981e+09 | AA33: 4.0361926e+09 | AB33: 3.4309492e+09
A34: GDP (current US$) | B34: NY.GDP.MKTP.CD | C34: Cabo Verde | D34: CPV | E34: 5.3922728e+08 | F34: 5.6309049e+08 | G34: 6.2050739e+08 | H34: 8.1326047e+08 | I34: 9.2494001e+08 | J34: 9.7224168e+08 | K34: 1.1075715e+09 | L34: 1.6496217e+09 | M34: 1.9596206e+09 | N34: 1.8523346e+09 | O34: 1.8247515e+09 | P34: 2.046818e+09 | Q34: 1.9130812e+09 | R34: 2.0289109e+09 | S34: 2.0419301e+09 | T34: 1.7498576e+09 | U34: 1.84979e+09 | V34: 1.9967415e+09 | W34: 2.2050995e+09 | X34: 2.2521771e+09 | Y34: 1.8215656e+09 | Z34: 2.0518426e+09 | AA34: 2.2470033e+09 | AB34: 2.5045255e+09
A35: GDP (current US$) | B35: NY.GDP.MKTP.CD | C35: Cambodia | D35: KHM | E35: 3.694169e+09 | F35: 4.145666e+09 | G35: 4.5012276e+09 | H35: 5.0466935e+09 | I35: 5.8832972e+09 | J35: 7.0662965e+09 | K35: 8.350531e+09 | L35: 1.0127916e+10 | M35: 1.2174304e+10 | N35: 1.2502901e+10 | O35: 1.3808673e+10 | P35: 1.6032622e+10 | Q35: 1.7826537e+10 | R35: 1.9807135e+10 | S35: 2.2041464e+10 | T35: 2.417417e+10 | U35: 2.6556545e+10 | V35: 2.9355666e+10 | W35: 3.3145892e+10 | X35: 3.6685356e+10 | Y35: 3.4818074e+10 | Z35: 3.6790164e+10 | AA35: 3.9994533e+10 | AB35: 4.2335647e+10
A36: GDP (current US$) | B36: NY.GDP.MKTP.CD | C36: Cameroon | D36: CMR | E36: 1.0566579e+10 | F36: 1.0953485e+10 | G36: 1.2417251e+10 | H36: 1.5970315e+10 | I36: 1.8826214e+10 | J36: 1.9509852e+10 | K36: 2.0910513e+10 | L36: 2.392825e+10 | M36: 2.7715142e+10 | N36: 2.793297e+10 | O36: 2.7507502e+10 | P36: 3.063091e+10 | Q36: 3.0155062e+10 | R36: 3.3728621e+10 | S36: 3.6386545e+10 | T36: 3.2210233e+10 | U36: 3.3814337e+10 | V36: 3.6098547e+10 | W36: 3.9955552e+10 | X36: 3.9667758e+10 | Y36: 4.0773241e+10 | Z36: 4.5011937e+10 | AA36: 4.4347206e+10 | AB36: 4.8814502e+10
A37: GDP (current US$) | B37: NY.GDP.MKTP.CD | C37: Canada | D37: CAN | E37: 7.4477342e+11 | F37: 7.3898179e+11 | G37: 7.6064933e+11 | H37: 8.9554065e+11 | I37: 1.0266902e+12 | J37: 1.1731086e+12 | K37: 1.3192648e+12 | L37: 1.4688204e+12 | M37: 1.5529897e+12 | N37: 1.3746251e+12 | O37: 1.6173434e+12 | P37: 1.7933266e+12 | Q37: 1.8283665e+12 | R37: 1.8465974e+12 | S37: 1.8057499e+12 | T37: 1.5565088e+12 | U37: 1.5279947e+12 | V37: 1.6492656e+12 | W37: 1.7253292e+12 | X37: 1.7437252e+12 | Y37: 1.6556847e+12 | Z37: 2.0223787e+12 | AA37: 2.1904111e+12 | AB37: 2.1733397e+12
A38: GDP (current US$) | B38: NY.GDP.MKTP.CD | C38: Cayman Islands | D38: CYM | E38: .. | F38: .. | G38: .. | H38: .. | I38: .. | J38: .. | K38: 4.2002883e+09 | L38: 4.466278e+09 | M38: 4.585949e+09 | N38: 4.2817146e+09 | O38: 4.1568412e+09 | P38: 4.1860732e+09 | Q38: 4.2910045e+09 | R38: 4.4057961e+09 | S38: 4.5628536e+09 | T38: 4.7081673e+09 | U38: 4.9093222e+09 | V38: 5.1662813e+09 | W38: 5.5301785e+09 | X38: 5.9418966e+09 | Y38: 5.655358e+09 | Z38: 6.0608138e+09 | AA38: 6.6601612e+09 | AB38: 7.2412443e+09
A39: GDP (current US$) | B39: NY.GDP.MKTP.CD | C39: Central African Republic | D39: CAF | E39: 9.1677728e+08 | F39: 9.326486e+08 | G39: 9.9606814e+08 | H39: 1.1423155e+09 | I39: 1.2723605e+09 | J39: 1.3378944e+09 | K39: 1.4618598e+09 | L39: 1.6998113e+09 | M39: 1.9934079e+09 | N39: 2.0673817e+09 | O39: 2.1425915e+09 | P39: 2.4379827e+09 | Q39: 2.5101265e+09 | R39: 1.6915441e+09 | S39: 1.8948134e+09 | T39: 1.6958257e+09 | U39: 1.8250181e+09 | V39: 2.07235e+09 | W39: 2.2209791e+09 | X39: 2.2213014e+09 | Y39: 2.3267209e+09 | Z39: 2.5164984e+09 | AA39: 2.3826186e+09 | AB39: 2.5554921e+09
A40: GDP (current US$) | B40: NY.GDP.MKTP.CD | C40: Chad | D40: TCD | E40: 1.3885068e+09 | F40: 1.7108434e+09 | G40: 1.9970057e+09 | H40: 2.7428151e+09 | I40: 4.4228557e+09 | J40: 8.6558924e+09 | K40: 9.7096266e+09 | L40: 1.0865385e+10 | M40: 1.3385594e+10 | N40: 1.2317614e+10 | O40: 1.4058507e+10 | P40: 1.668535e+10 | Q40: 1.7892229e+10 | R40: 1.7865317e+10 | S40: 1.8144337e+10 | T40: 1.4559599e+10 | U40: 1.302629e+10 | V40: 1.3349041e+10 | W40: 1.5327e+10 | X40: 1.4905518e+10 | Y40: 1.4932898e+10 | Z40: 1.6871938e+10 | AA40: 1.7828508e+10 | AB40: 1.8340234e+10
A41: GDP (current US$) | B41: NY.GDP.MKTP.CD | C41: Channel Islands | D41: CHI | E41: 6.4397034e+09 | F41: 6.2329063e+09 | G41: 6.6636691e+09 | H41: 7.3322449e+09 | I41: 8.5536434e+09 | J41: 8.8272727e+09 | K41: 9.676173e+09 | L41: 1.1514606e+10 | M41: .. | N41: 9.1007557e+09 | O41: 8.9023593e+09 | P41: 9.64868e+09 | Q41: 9.4546381e+09 | R41: 9.5947458e+09 | S41: 1.0527973e+10 | T41: 1.0109274e+10 | U41: 9.1688572e+09 | V41: 9.1700445e+09 | W41: 1.0026394e+10 | X41: 1.0031865e+10 | Y41: 9.4398108e+09 | Z41: 1.115754e+10 | AA41: 1.1308273e+10 | AB41: 1.2507321e+10
A42: GDP (current US$) | B42: NY.GDP.MKTP.CD | C42: Chile | D42: CHL | E42: 7.8339751e+10 | F42: 7.157474e+10 | G42: 7.0264046e+10 | H42: 7.649258e+10 | I42: 9.9075986e+10 | J42: 1.2229415e+11 | K42: 1.5384352e+11 | L42: 1.7249108e+11 | M42: 1.7989459e+11 | N42: 1.717779e+11 | O42: 2.1705121e+11 | P42: 2.5138257e+11 | Q42: 2.6702478e+11 | R42: 2.7739502e+11 | S42: 2.5956098e+11 | T42: 2.4245036e+11 | U42: 2.4934486e+11 | V42: 2.7615426e+11 | W42: 2.9585756e+11 | X42: 2.7828506e+11 | Y42: 2.5404216e+11 | Z42: 3.1532555e+11 | AA42: 3.0122658e+11 | AB42: 3.3551805e+11
A43: GDP (current US$) | B43: NY.GDP.MKTP.CD | C43: China | D43: CHN | E43: 1.2237549e+12 | F43: 1.3550366e+12 | G43: 1.4898217e+12 | H43: 1.6839033e+12 | I43: 1.9841966e+12 | J43: 2.3175513e+12 | K43: 2.7914985e+12 | L43: 3.6040558e+12 | M43: 4.6673464e+12 | N43: 5.1895771e+12 | O43: 6.1925649e+12 | P43: 7.6717572e+12 | Q43: 8.6736647e+12 | R43: 9.7431242e+12 | S43: 1.0674533e+13 | T43: 1.1280815e+13 | U43: 1.1456024e+13 | V43: 1.2537559e+13 | W43: 1.4147766e+13 | X43: 1.4560167e+13 | Y43: 1.4996414e+13 | Z43: 1.8201699e+13 | AA43: 1.8316765e+13 | AB43: 1.8270357e+13
A44: GDP (current US$) | B44: NY.GDP.MKTP.CD | C44: Colombia | D44: COL | E44: 9.9875075e+10 | F44: 9.8200641e+10 | G44: 9.7945813e+10 | H44: 9.4644969e+10 | I44: 1.1709242e+11 | J44: 1.4560053e+11 | K44: 1.6179296e+11 | L44: 2.0622954e+11 | M44: 2.4250415e+11 | N44: 2.3246866e+11 | O44: 2.8649853e+11 | P44: 3.3496613e+11 | Q44: 3.7069114e+11 | R44: 3.820937e+11 | S44: 3.8124086e+11 | T44: 2.9349237e+11 | U44: 2.827201e+11 | V44: 3.1186688e+11 | W44: 3.3419822e+11 | X44: 3.230317e+11 | Y44: 2.7034834e+11 | Z44: 3.1852463e+11 | AA44: 3.4563249e+11 | AB44: 3.6629184e+11
A45: GDP (current US$) | B45: NY.GDP.MKTP.CD | C45: Comoros | D45: COM | E45: 3.3950431e+08 | F45: 3.7274649e+08 | G45: 4.2736007e+08 | H45: 5.4683004e+08 | I45: 6.2267966e+08 | J45: 6.553751e+08 | K45: 6.8849864e+08 | L45: 7.9567315e+08 | M45: 9.1565911e+08 | N45: 9.0534117e+08 | O45: 9.0797873e+08 | P45: 1.0230863e+09 | Q45: 1.0158435e+09 | R45: 1.1162241e+09 | S45: 1.1495877e+09 | T45: 9.660296e+08 | U45: 1.0128355e+09 | V45: 1.0774398e+09 | W45: 1.1785306e+09 | X45: 1.1879154e+09 | Y45: 1.2187637e+09 | Z45: 1.2722384e+09 | AA45: 1.2224855e+09 | AB45: 1.3268365e+09
A46: GDP (current US$) | B46: NY.GDP.MKTP.CD | C46: Congo, Dem. Rep. | D46: COD | E46: 1.9088046e+10 | F46: 7.4381891e+09 | G46: 8.7280385e+09 | H46: 8.9375671e+09 | I46: 1.0297483e+10 | J46: 1.2609729e+10 | K46: 1.5484045e+10 | L46: 1.8374808e+10 | M46: 2.2723489e+10 | N46: 1.8607259e+10 | O46: 2.4161642e+10 | P46: 2.639238e+10 | Q46: 3.002937e+10 | R46: 3.4891189e+10 | S46: 3.8352981e+10 | T46: 4.0179574e+10 | U46: 3.8600224e+10 | V46: 3.7537522e+10 | W46: 4.6659954e+10 | X46: 4.68459e+10 | Y46: 4.669199e+10 | Z46: 5.906729e+10 | AA46: 7.0422346e+10 | AB46: 6.9843655e+10
A47: GDP (current US$) | B47: NY.GDP.MKTP.CD | C47: Congo, Rep. | D47: COG | E47: 3.2279277e+09 | F47: 2.7967046e+09 | G47: 3.0342509e+09 | H47: 3.5037231e+09 | I47: 4.6569749e+09 | J47: 6.6500017e+09 | K47: 8.072305e+09 | L47: 8.7827034e+09 | M47: 1.1649858e+10 | N47: 9.7232999e+09 | O47: 1.3148396e+10 | P47: 1.5655384e+10 | Q47: 1.7692911e+10 | R47: 1.7958721e+10 | S47: 1.7919321e+10 | T47: 1.2434794e+10 | U47: 1.0931328e+10 | V47: 1.1834473e+10 | W47: 1.47739e+10 | X47: 1.3976638e+10 | Y47: 1.1468687e+10 | Z47: 1.482569e+10 | AA47: 1.581703e+10 | AB47: 1.5321056e+10
A48: GDP (current US$) | B48: NY.GDP.MKTP.CD | C48: Costa Rica | D48: CRI | E48: 1.501363e+10 | F48: 1.5976174e+10 | G48: 1.6578821e+10 | H48: 1.7271761e+10 | I48: 1.8610595e+10 | J48: 2.0040642e+10 | K48: 2.271554e+10 | L48: 2.6884701e+10 | M48: 3.0801746e+10 | N48: 3.0745714e+10 | O48: 3.7658617e+10 | P48: 4.2762614e+10 | Q48: 4.7231655e+10 | R48: 5.0949669e+10 | S48: 5.2016409e+10 | T48: 5.6441921e+10 | U48: 5.884702e+10 | V48: 6.0516045e+10 | W48: 6.2420165e+10 | X48: 6.4417671e+10 | Y48: 6.2395611e+10 | Z48: 6.4960726e+10 | AA48: 6.9243626e+10 | AB48: 8.6497941e+10
A49: GDP (current US$) | B49: NY.GDP.MKTP.CD | C49: Cote d'Ivoire | D49: CIV | E49: 1.6577534e+10 | F49: 1.6810537e+10 | G49: 1.8054383e+10 | H49: 2.1251754e+10 | I49: 2.3510576e+10 | J49: 2.4036919e+10 | K49: 2.5281413e+10 | L49: 2.8760091e+10 | M49: 3.407824e+10 | N49: 3.3886813e+10 | O49: 3.4936308e+10 | P49: 3.6693711e+10 | Q49: 3.6302303e+10 | R49: 4.2760235e+10 | S49: 4.8843006e+10 | T49: 4.5815005e+10 | U49: 4.8407761e+10 | V49: 5.2512344e+10 | W49: 5.8522478e+10 | X49: 6.0382895e+10 | Y49: 6.3027853e+10 | Z49: 7.2794637e+10 | AA49: 7.0922825e+10 | AB49: 8.0780313e+10
A50: GDP (current US$) | B50: NY.GDP.MKTP.CD | C50: Croatia | D50: HRV | E50: 2.2134411e+10 | F50: 2.3066884e+10 | G50: 2.6757722e+10 | H50: 3.5245317e+10 | I50: 4.1836292e+10 | J50: 4.5013119e+10 | K50: 4.9583545e+10 | L50: 5.9290621e+10 | M50: 6.8472855e+10 | N50: 6.2315997e+10 | O50: 5.8975205e+10 | P50: 6.2889008e+10 | Q50: 5.7548116e+10 | R50: 5.9846265e+10 | S50: 5.9606935e+10 | T50: 5.0998893e+10 | U50: 5.2650714e+10 | V50: 5.6182783e+10 | W50: 6.1667925e+10 | X50: 6.1466721e+10 | Y50: 5.7959844e+10 | Z50: 6.9002365e+10 | AA50: 7.1196499e+10 | AB50: 8.5624154e+10
...

Sheet CH4_Em
A1: Series Name | B1: Series Code | C1: Country Name | D1: Country Code | E1: 2000 | F1: 2001 | G1: 2002 | H1: 2003 | I1: 2004 | J1: 2005 | K1: 2006 | L1: 2007 | M1: 2008 | N1: 2009 | O1: 2010 | P1: 2011 | Q1: 2012 | R1: 2013 | S1: 2014 | T1: 2015 | U1: 2016 | V1: 2017 | W1: 2018 | X1: 2019 | Y1: 2020 | Z1: 2021 | AA1: 2022 | AB1: 2023 | AC1: 2024 | AD1: 2025
A2: Methane (CH4) emissions from Agriculture (Mt CO2e) | B2: EN.GHG.CH4.AG.MT.CE.AR5 | C2: Afghanistan | D2: AFG | E2: 9.5435 | F2: 8.012 | G2: 10.1641 | H2: 10.5081 | I2: 10.6837 | J2: 10.2225 | K2: 10.2411 | L2: 10.5647 | M2: 11.6608 | N2: 12.0455 | O2: 13.6515 | P2: 13.5864 | Q2: 13.1225 | R2: 12.8916 | S2: 13.2465 | T2: 12.4692 | U2: 11.9603 | V2: 11.5819 | W2: 11.8867 | X2: 12.053 | Y2: 12.3271 | Z2: 12.3193 | AA2: 12.3824 | AB2: 12.3887 | AC2: 12.4833 | AD2: ..
A3: Methane (CH4) emissions from Agriculture (Mt CO2e) | B3: EN.GHG.CH4.AG.MT.CE.AR6 | C3: Albania | D3: ALB | E3: 2.3928 | F3: 2.3545 | G3: 2.3091 | H3: 2.341 | I3: 2.2458 | J3: 2.2002 | K3: 2.1779 | L3: 2.0644 | M3: 1.9492 | N3: 1.8525 | O3: 1.8668 | P3: 1.8729 | Q3: 1.9231 | R3: 1.9663 | S3: 2.0053 | T3: 2.0165 | U3: 2.0009 | V3: 1.9533 | W3: 1.9102 | X3: 1.7559 | Y3: 1.5737 | Z3: 1.4787 | AA3: 1.35 | AB3: 1.2102 | AC3: 1.0701 | AD3: ..
A4: Methane (CH4) emissions from Agriculture (Mt CO2e) | B4: EN.GHG.CH4.AG.MT.CE.AR7 | C4: Algeria | D4: DZA | E4: 5.6225 | F4: 5.6497 | G4: 5.4883 | H4: 5.6301 | I4: 5.8711 | J4: 5.9283 | K4: 6.1188 | L4: 6.1983 | M4: 6.1633 | N4: 6.4622 | O4: 6.8783 | P4: 7.239 | Q4: 7.5631 | R4: 7.8728 | S4: 8.4059 | T4: 8.6527 | U4: 8.5602 | V4: 8.3831 | W4: 8.2957 | X4: 8.3528 | Y4: 8.5234 | Z4: 8.5833 | AA4: 8.6426 | AB4: 8.8292 | AC4: 8.936 | AD4: ..
A5: Methane (CH4) emissions from Agriculture (Mt CO2e) | B5: EN.GHG.CH4.AG.MT.CE.AR8 | C5: American Samoa | D5: ASM | E5: 0.004 | F5: 0.004 | G5: 0.004 | H5: 0.004 | I5: 0.004 | J5: 0.004 | K5: 0.004 | L5: 0.004 | M5: 0.004 | N5: 0.004 | O5: 0.004 | P5: 0.004 | Q5: 0.004 | R5: 0.004 | S5: 0.004 | T5: 0.004 | U5: 0.004 | V5: 0.004 | W5: 0.004 | X5: 0.004 | Y5: 0.004 | Z5: 0.004 | AA5: 0.004 | AB5: 0.004 | AC5: 0.004 | AD5: ..
A6: Methane (CH4) emissions from Agriculture (Mt CO2e) | B6: EN.GHG.CH4.AG.MT.CE.AR9 | C6: Andorra | D6: AND | E6: .. | F6: .. | G6: .. | H6: .. | I6: .. | J6: .. | K6: .. | L6: .. | M6: .. | N6: .. | O6: .. | P6: .. | Q6: .. | R6: .. | S6: .. | T6: .. | U6: .. | V6: .. | W6: .. | X6: .. | Y6: .. | Z6: .. | AA6: .. | AB6: .. | AC6: .. | AD6: ..
A7: Methane (CH4) emissions from Agriculture (Mt CO2e) | B7: EN.GHG.CH4.AG.MT.CE.AR10 | C7: Angola | D7: AGO | E7: 5.1767 | F7: 5.1887 | G7: 5.1233 | H7: 5.0531 | I7: 4.9469 | J7: 5.3786 | K7: 5.4981 | L7: 5.6415 | M7: 5.7552 | N7: 5.9338 | O7: 6.0847 | P7: 6.2484 | Q7: 6.327 | R7: 6.5573 | S7: 6.6956 | T7: 6.8523 | U7: 6.9685 | V7: 6.8481 | W7: 6.8036 | X7: 7.0802 | Y7: 7.1146 | Z7: 7.1939 | AA7: 7.2824 | AB7: 7.1879 | AC7: 7.2478 | AD7: ..
A8: Methane (CH4) emissions from Agriculture (Mt CO2e) | B8: EN.GHG.CH4.AG.MT.CE.AR11 | C8: Antigua and Barbuda | D8: ATG | E8: 0.031 | F8: 0.0319 | G8: 0.0324 | H8: 0.0328 | I8: 0.0335 | J8: 0.0334 | K8: 0.0336 | L8: 0.0335 | M8: 0.0334 | N8: 0.0333 | O8: 0.0158 | P8: 0.0159 | Q8: 0.0159 | R8: 0.0159 | S8: 0.0159 | T8: 0.0159 | U8: 0.0158 | V8: 0.0159 | W8: 0.0149 | X8: 0.0125 | Y8: 0.012 | Z8: 0.0116 | AA8: 0.0112 | AB8: 0.0129 | AC8: 0.0125 | AD8: ..
A9: Methane (CH4) emissions from Agriculture (Mt CO2e) | B9: EN.GHG.CH4.AG.MT.CE.AR12 | C9: Argentina | D9: ARG | E9: 95.5734 | F9: 95.6984 | G9: 100.8519 | H9: 107.8627 | I9: 109.997 | J9: 110.7595 | K9: 113.2453 | L9: 114.3336 | M9: 112.5107 | N9: 106.4416 | O9: 97.6415 | P9: 96.1654 | Q9: 99.1014 | R9: 101.3174 | S9: 102.15 | T9: 101.5162 | U9: 103.0171 | V9: 106.9121 | W9: 106.3249 | X9: 107.1145 | Y9: 106.0454 | Z9: 103.9611 | AA9: 105.2629 | AB9: 104.5161 | AC9: 105.3821 | AD9: ..
A10: Methane (CH4) emissions from Agriculture (Mt CO2e) | B10: EN.GHG.CH4.AG.MT.CE.AR13 | C10: Armenia | D10: ARM | E10: 1.2064 | F10: 1.2412 | G10: 1.2985 | H10: 1.3542 | I10: 1.4253 | J10: 1.4213 | K10: 1.4525 | L10: 1.5153 | M10: 1.521 | N10: 1.4068 | O10: 1.3692 | P10: 1.3699 | Q10: 1.4408 | R10: 1.5874 | S10: 1.634 | T10: 1.6612 | U10: 1.6965 | V10: 1.5844 | W10: 1.4392 | X10: 1.3917 | Y10: 1.4126 | Z10: 1.4899 | AA10: 1.3852 | AB10: 1.2614 | AC10: 1.2631 | AD10: ..
A11: Methane (CH4) emissions from Agriculture (Mt CO2e) | B11: EN.GHG.CH4.AG.MT.CE.AR14 | C11: Aruba | D11: ABW | E11: 0.0014 | F11: 0.0014 | G11: 0.0014 | H11: 0.0014 | I11: 0.0014 | J11: 0.0014 | K11: 0.0014 | L11: 0.0014 | M11: 0.0014 | N11: 0.0014 | O11: 0.0014 | P11: 0.0014 | Q11: 0.0014 | R11: 0.0014 | S11: 0.0014 | T11: 0.0014 | U11: 0.0014 | V11: 0.0014 | W11: 0.0014 | X11: 0.0014 | Y11: 0.0014 | Z11: 0.0015 | AA11: 0.0015 | AB11: 0.0015 | AC11: 0.0015 | AD11: ..
A12: Methane (CH4) emissions from Agriculture (Mt CO2e) | B12: EN.GHG.CH4.AG.MT.CE.AR15 | C12: Australia | D12: AUS | E12: 88.5281 | F12: 87.5876 | G12: 86.8955 | H12: 82.2352 | I12: 85.0559 | J12: 85.5892 | K12: 85.0017 | L12: 82.57 | M12: 78.6682 | N12: 79.3246 | O12: 75.9109 | P12: 81.325 | Q12: 82.1396 | R12: 84.3242 | S12: 83.241 | T12: 79.6591 | U12: 73.421 | V12: 77.3679 | W12: 77.2308 | X12: 72.1408 | Y12: 69.0154 | Z12: 72.5942 | AA12: 73.0429 | AB12: 84.6281 | AC12: 84.701 | AD12: ..
A13: Methane (CH4) emissions from Agriculture (Mt CO2e) | B13: EN.GHG.CH4.AG.MT.CE.AR16 | C13: Austria | D13: AUT | E13: 5.7815 | F13: 5.7875 | G13: 5.7419 | H13: 5.5893 | I13: 5.5172 | J13: 5.4 | K13: 5.4204 | L13: 5.3954 | M13: 5.4458 | N13: 5.4313 | O13: 5.5451 | P13: 5.5543 | Q13: 5.471 | R13: 5.4509 | S13: 5.4632 | T13: 5.4809 | U13: 5.4718 | V13: 5.4694 | W13: 5.3837 | X13: 5.3065 | Y13: 5.2711 | Z13: 5.3001 | AA13: 5.2986 | AB13: 5.2077 | AC13: 5.2082 | AD13: ..
A14: Methane (CH4) emissions from Agriculture (Mt CO2e) | B14: EN.GHG.CH4.AG.MT.CE.AR17 | C14: Azerbaijan | D14: AZE | E14: 5.3504 | F14: 5.6479 | G14: 5.8418 | H14: 6.1121 | I14: 6.3158 | J14: 6.5094 | K14: 6.7816 | L14: 6.9669 | M14: 7.1762 | N14: 7.3445 | O14: 7.4423 | P14: 7.4784 | Q14: 7.5557 | R14: 7.6589 | S14: 7.7698 | T14: 7.8144 | U14: 7.7938 | V14: 7.7395 | W14: 7.6691 | X14: 7.6327 | Y14: 7.5896 | Z14: 7.5401 | AA14: 7.4591 | AB14: 7.1169 | AC14: 7.0345 | AD14: ..
A15: Methane (CH4) emissions from Agriculture (Mt CO2e) | B15: EN.GHG.CH4.AG.MT.CE.AR18 | C15: Bahamas, The | D15: BHS | E15: 0.0055 | F15: 0.0057 | G15: 0.0054 | H15: 0.0057 | I15: 0.0059 | J15: 0.0059 | K15: 0.0059 | L15: 0.006 | M15: 0.006 | N15: 0.006 | O15: 0.006 | P15: 0.006 | Q15: 0.0061 | R15: 0.0061 | S15: 0.0061 | T15: 0.0061 | U15: 0.0061 | V15: 0.0061 | W15: 0.0061 | X15: 0.0061 | Y15: 0.0061 | Z15: 0.0061 | AA15: 0.0061 | AB15: 0.0062 | AC15: 0.0062 | AD15: ..
A16: Methane (CH4) emissions from Agriculture (Mt CO2e) | B16: EN.GHG.CH4.AG.MT.CE.AR19 | C16: Bahrain | D16: BHR | E16: 0.0248 | F16: 0.0225 | G16: 0.0305 | H16: 0.0258 | I16: 0.0231 | J16: 0.0242 | K16: 0.0235 | L16: 0.0236 | M16: 0.0199 | N16: 0.02 | O16: 0.0237 | P16: 0.0238 | Q16: 0.0242 | R16: 0.0248 | S16: 0.0247 | T16: 0.0238 | U16: 0.0238 | V16: 0.0237 | W16: 0.0268 | X16: 0.0277 | Y16: 0.0255 | Z16: 0.0265 | AA16: 0.0272 | AB16: 0.0267 | AC16: 0.0267 | AD16: ..
A17: Methane (CH4) emissions from Agriculture (Mt CO2e) | B17: EN.GHG.CH4.AG.MT.CE.AR20 | C17: Bangladesh | D17: BGD | E17: 44.2718 | F17: 44.2104 | G17: 44.9228 | H17: 45.2811 | I17: 44.8767 | J17: 45.7369 | K17: 46.3095 | L17: 46.7482 | M17: 48.2702 | N17: 48.8431 | O17: 49.5964 | P17: 50.0417 | Q17: 50.2725 | R17: 50.4681 | S17: 50.7275 | T17: 50.8555 | U17: 50.4119 | V17: 51.5698 | W17: 51.6336 | X17: 51.8718 | Y17: 52.0419 | Z17: 52.7777 | AA17: 53.0532 | AB17: 48.5841 | AC17: 47.4059 | AD17: ..
A18: Methane (CH4) emissions from Agriculture (Mt CO2e) | B18: EN.GHG.CH4.AG.MT.CE.AR21 | C18: Barbados | D18: BRB | E18: 0.0492 | F18: 0.0448 | G18: 0.0416 | H18: 0.0383 | I18: 0.0353 | J18: 0.0326 | K18: 0.0278 | L18: 0.0255 | M18: 0.0266 | N18: 0.029 | O18: 0.0288 | P18: 0.0287 | Q18: 0.0291 | R18: 0.029 | S18: 0.0288 | T18: 0.0285 | U18: 0.0283 | V18: 0.0286 | W18: 0.0288 | X18: 0.0297 | Y18: 0.0302 | Z18: 0.0305 | AA18: 0.0309 | AB18: 0.028 | AC18: 0.0279 | AD18: ..
... A40: Methane (CH4) emissions from Agriculture (Mt CO2e) | B40: EN.GHG.CH4.AG.MT.CE.AR43 | C40: Chad | D40: TCD | E40: 17.3709 | F40: 18.3822 | G40: 19.4585 | H40: 20.5807 | I40: 21.7339 | J40: 23.0214 | K40: 24.3422 | L40: 25.7784 | M40: 27.3238 | N40: 28.9236 | O40: 30.6627 | P40: 32.331 | Q40: 34.2365 | R40: 36.3421 | S40: 38.3718 | T40: 41.6311 | U40: 44.062 | V40: 46.6975 | W40: 49.4449 | X40: 52.3764 | Y40: 55.4601 | Z40: 58.1151 | AA40: 61.9805 | AB40: 65.8737 | AC40: 69.1677 | AD40: ..
A41: Methane (CH4) emissions from Agriculture (Mt CO2e) | B41: EN.GHG.CH4.AG.MT.CE.AR44 | C41: Channel Islands | D41: CHI | E41: .. | F41: .. | G41: .. | H41: .. | I41: .. | J41: .. | K41: .. | L41: .. | M41: .. | N41: .. | O41: .. | P41: .. | Q41: .. | R41: .. | S41: .. | T41: .. | U41: .. | V41: .. | W41: .. | X41: .. | Y41: .. | Z41: .. | AA41: .. | AB41: .. | AC41: .. | AD41: ..
A42: Methane (CH4) emissions from Agriculture (Mt CO2e) | B42: EN.GHG.CH4.AG.MT.CE.AR45 | C42: Chile | D42: CHL | E42: 9.0012 | F42: 8.9113 | G42: 8.8224 | H42: 8.7841 | I42: 8.9029 | J42: 8.8807 | K42: 8.7887 | L42: 8.4909 | M42: 8.6451 | N42: 8.7544 | O42: 8.7017 | P42: 8.6254 | Q42: 8.6755 | R42: 7.1549 | S42: 6.7966 | T42: 6.4143 | U42: 6.5836 | V42: 6.6588 | W42: 6.8836 | X42: 7.1222 | Y42: 7.2805 | Z42: 6.8801 | AA42: 6.7649 | AB42: 6.6331 | AC42: 6.6465 | AD42: ..
A43: Methane (CH4) emissions from Agriculture (Mt CO2e) | B43: EN.GHG.CH4.AG.MT.CE.AR46 | C43: China | D43: CHN | E43: 513.0751 | F43: 497.2657 | G43: 485.179 | H43: 469.4213 | I43: 487.4993 | J43: 487.9955 | K43: 488.4152 | L43: 480.1766 | M43: 489.4613 | N43: 488.617 | O43: 486.7554 | P43: 483.7363 | Q43: 483.3797 | R43: 483.2052 | S43: 484.9423 | T43: 487.3929 | U43: 488.1849 | V43: 481.1923 | W43: 478.809 | X43: 465.559 | Y43: 475.7055 | Z43: 480.2183 | AA43: 477.155 | AB43: 500.243 | AC43: 498.9837 | AD43: ..
A44: Methane (CH4) emissions from Agriculture (Mt CO2e) | B44: EN.GHG.CH4.AG.MT.CE.AR47 | C44: Colombia | D44: COL | E44: 47.5617 | F44: 47.8775 | G44: 48.1491 | H44: 48.6765 | I44: 49.0249 | J44: 49.9482 | K44: 50.3491 | L44: 51.456 | M44: 52.2837 | N44: 52.0509 | O44: 53.1813 | P44: 50.209 | Q44: 47.6684 | R44: 47.3491 | S44: 45.0824 | T44: 44.5227 | U44: 45.7483 | V44: 48.7999 | W44: 51.8404 | X44: 54.2887 | Y44: 56.1059 | Z44: 58.7012 | AA44: 58.7654 | AB44: 58.7372 | AC44: 58.8592 | AD44: ..
A45: Methane (CH4) emissions from Agriculture (Mt CO2e) | B45: EN.GHG.CH4.AG.MT.CE.AR48 | C45: Comoros | D45: COM | E45: 0.0795 | F45: 0.0812 | G45: 0.0829 | H45: 0.0732 | I45: 0.0759 | J45: 0.0735 | K45: 0.075 | L45: 0.0748 | M45: 0.0741 | N45: 0.0731 | O45: 0.0709 | P45: 0.0715 | Q45: 0.0714 | R45: 0.0716 | S45: 0.0714 | T45: 0.0715 | U45: 0.0718 | V45: 0.0721 | W45: 0.0723 | X45: 0.0724 | Y45: 0.0722 | Z45: 0.0723 | AA45: 0.0724 | AB45: 0.0725 | AC45: 0.0725 | AD45: ..
A46: Methane (CH4) emissions from Agriculture (Mt CO2e) | B46: EN.GHG.CH4.AG.MT.CE.AR49 | C46: Congo, Dem. Rep. | D46: COD | E46: 1.8523 | F46: 1.802 | G46: 1.7503 | H46: 1.7509 | I46: 1.7518 | J46: 1.7521 | K46: 1.7532 | L46: 1.7535 | M46: 1.7554 | N46: 1.7552 | O46: 1.9209 | P46: 1.9193 | Q46: 2.0619 | R46: 2.1649 | S46: 2.2258 | T46: 2.2909 | U46: 2.3436 | V46: 2.4002 | W46: 2.4726 | X46: 2.5478 | Y46: 2.6834 | Z46: 2.8542 | AA46: 3.0381 | AB46: 3.3299 | AC46: 3.5031 | AD46: ..
A47: Methane (CH4) emissions from Agriculture (Mt CO2e) | B47: EN.GHG.CH4.AG.MT.CE.AR50 | C47: Congo, Rep. | D47: COG | E47: 0.1613 | F47: 0.1649 | G47: 0.171 | H47: 0.1783 | I47: 0.2326 | J47: 0.2872 | K47: 0.3458 | L47: 0.4077 | M47: 0.4448 | N47: 0.4385 | O47: 0.4699 | P47: 0.4743 | Q47: 0.4745 | R47: 0.4746 | S47: 0.4774 | T47: 0.4767 | U47: 0.476 | V47: 0.4747 | W47: 0.4735 | X47: 0.4739 | Y47: 0.4725 | Z47: 0.4719 | AA47: 0.4717 | AB47: 0.4626 | AC47: 0.4604 | AD47: ..
A48: Methane (CH4) emissions from Agriculture (Mt CO2e) | B48: EN.GHG.CH4.AG.MT.CE.AR51 | C48: Costa Rica | D48: CRI | E48: 3.0603 | F48: 2.8899 | G48: 2.7338 | H48: 2.6521 | I48: 2.5637 | J48: 2.6796 | K48: 2.5771 | L48: 2.7619 | M48: 2.9652 | N48: 3.0329 | O48: 3.1757 | P48: 3.2074 | Q48: 2.9875 | R48: 3.0618 | S48: 2.9377 | T48: 2.9812 | U48: 3.142 | V48: 3.2351 | W48: 3.4267 | X48: 3.4991 | Y48: 3.1262 | Z48: 3.4655 | AA48: 3.5189 | AB48: 4.3964 | AC48: 4.383 | AD48: ..
A49: Methane (CH4) emissions from Agriculture (Mt CO2e) | B49: EN.GHG.CH4.AG.MT.CE.AR52 | C49: Cote d'Ivoire | D49: CIV | E49: 2.1522 | F49: 2.1934 | G49: 2.2344 | H49: 2.2733 | I49: 2.316 | J49: 2.3692 | K49: 2.4224 | L49: 2.4455 | M49: 2.5078 | N49: 2.5643 | O49: 2.642 | P49: 2.5957 | Q49: 2.8464 | R49: 2.9643 | S49: 3.0076 | T49: 3.0539 | U49: 3.1476 | V49: 3.2967 | W49: 3.3704 | X49: 3.4195 | Y49: 3.3829 | Z49: 3.5358 | AA49: 3.5096 | AB49: 3.7948 | AC49: 3.8818 | AD49: ..
A50: Methane (CH4) emissions from Agriculture (Mt CO2e) | B50: EN.GHG.CH4.AG.MT.CE.AR53 | C50: Croatia | D50: HRV | E50: 1.4507 | F50: 1.5052 | G50: 1.4865 | H50: 1.5533 | I50: 1.6763 | J50: 1.6329 | K50: 1.6533 | L50: 1.5799 | M50: 1.4912 | N50: 1.4646 | O50: 1.4162 | P50: 1.4799 | Q50: 1.5388 | R50: 1.5271 | S50: 1.6293 | T50: 1.6831 | U50: 1.69 | V50: 1.71 | W50: 1.6049 | X50: 1.6298 | Y50: 1.6191 | Z50: 1.6247 | AA50: 1.5753 | AB50: 1.512 | AC50: 1.4934 | AD50: ..
A51: Methane (CH4) emissions from Agriculture (Mt CO2e) | B51: EN.GHG.CH4.AG.MT.CE.AR54 | C51: Cuba | D51: CUB | E51: 8.1137 | F51: 7.8998 | G51: 7.916 | H51: 7.934 | I51: 7.51 | J51: 6.8601 | K51: 7.1704 | L51: 7.3358 | M51: 7.6139 | N51: 8.0956 | O51: 8.0886 | P51: 8.3218 | Q51: 8.3925 | R51: 8.455 | S51: 8.4539 | T51: 8.0766 | U51: 8.1916 | V51: 7.8289 | W51: 7.8109 | X51: 7.7195 | Y51: 7.2902 | Z51: 7.0612 | AA51: 6.7823 | AB51: 6.5512 | AC51: 6.4221 | AD51: ..
A52: Methane (CH4) emissions from Agriculture (Mt CO2e) | B52: EN.GHG.CH4.AG.MT.CE.AR55 | C52: Curacao | D52: CUW | E52: .. | F52: .. | G52: .. | H52: .. | I52: .. | J52: .. | K52: .. | L52: .. | M52: .. | N52: .. | O52: .. | P52: .. | Q52: .. | R52: .. | S52: .. | T52: .. | U52: .. | V52: .. | W52: .. | X52: .. | Y52: .. | Z52: .. | AA52: .. | AB52: .. | AC52: .. | AD52: ..
A53: Methane (CH4) emissions from Agriculture (Mt CO2e) | B53: EN.GHG.CH4.AG.MT.CE.AR56 | C53: Cyprus | D53: CYP | E53: 0.349 | F53: 0.3729 | G53: 0.3948 | H53: 0.3778 | I53: 0.3687 | J53: 0.347 | K53: 0.3516 | L53: 0.347 | M53: 0.3484 | N53: 0.3498 | O53: 0.3649 | P53: 0.3714 | Q53: 0.3628 | R53: 0.3519 | S53: 0.3617 | T53: 0.3556 | U53: 0.3746 | V53: 0.3942 | W53: 0.4035 | X53: 0.4188 | Y53: 0.4571 | Z53: 0.4639 | AA53: 0.4489 | AB53: 0.4511 | AC53: 0.4597 | AD53: ..
A54: Methane (CH4) emissions from Agriculture (Mt CO2e) | B54: EN.GHG.CH4.AG.MT.CE.AR57 | C54: Czechia | D54: CZE | E54: 5.8753 | F54: 5.9327 | G54: 5.694 | H54: 5.4988 | I54: 5.3629 | J54: 5.1521 | K54: 5.1155 | L54: 5.1207 | M54: 5.1602 | N54: 5.0313 | O54: 5.0036 | P54: 4.95 | Q54: 4.9655 | R54: 5.0301 | S54: 5.1104 | T54: 5.2139 | U54: 5.2383 | V54: 5.226 | W54: 5.0647 | X54: 5.0731 | Y54: 4.9885 | Z54: 5.0347 | AA54: 5.1 | AB54: 5.0568 | AC54: 5.0507 | AD54: ..
A55: Methane (CH4) emissions from Agriculture (Mt CO2e) | B55: EN.GHG.CH4.AG.MT.CE.AR58 | C55: Denmark | D55: DNK | E55: 7.1602 | F55: 7.3207 | G55: 7.2077 | H55: 7.1392 | I55: 7.0484 | J55: 6.864 | K55: 6.7276 | L55: 6.8417 | M55: 6.688 | N55: 6.6371 | O55: 6.9336 | P55: 6.9035 | Q55: 6.9077 | R55: 6.8395 | S55: 6.7624 | T55: 6.7882 | U55: 6.8122 | V55: 6.7827 | W55: 6.8131 | X55: 6.7938 | Y55: 6.9329 | Z55: 6.8356 | AA55: 6.4641 | AB55: 6.3384 | AC55: 6.3396 | AD55: ..
A56: Methane (CH4) emissions from Agriculture (Mt CO2e) | B56: EN.GHG.CH4.AG.MT.CE.AR59 | C56: Djibouti | D56: DJI | E56: 0.5025 | F56: 0.5031 | G56: 0.5032 | H56: 0.5047 | I56: 0.5098 | J56: 0.5102 | K56: 0.5024 | L56: 0.5029 | M56: 0.5029 | N56: 0.5045 | O56: 0.5045 | P56: 0.5041 | Q56: 0.508 | R56: 0.508 | S56: 0.5099 | T56: 0.5117 | U56: 0.5138 | V56: 0.5158 | W56: 0.5174 | X56: 0.5112 | Y56: 0.511 | Z56: 0.511 | AA56: 0.5111 | AB56: 0.5218 | AC56: 0.5227 | AD56: ..
A57: Methane (CH4) emissions from Agriculture (Mt CO2e) | B57: EN.GHG.CH4.AG.MT.CE.AR60 | C57: Dominica | D57: DMA | E57: 0.0259 | F57: 0.0259 | G57: 0.0259 | H57: 0.0259 | I57: 0.0259 | J57: 0.0259 | K57: 0.026 | L57: 0.0261 | M57: 0.0261 | N57: 0.0261 | O57: 0.0263 | P57: 0.0267 | Q57: 0.0272 | R57: 0.0271 | S57: 0.0271 | T57: 0.027 | U57: 0.027 | V57: 0.027 | W57: 0.0269 | X57: 0.0271 | Y57: 0.0271 | Z57: 0.0271 | AA57: 0.0272 | AB57: 0.0272 | AC57: 0.0272 | AD57: ..
A58: Methane (CH4) emissions from Agriculture (Mt CO2e) | B58: EN.GHG.CH4.AG.MT.CE.AR61 | C58: Dominican Republic | D58: DOM | E58: 4.3499 | F58: 4.6036 | G58: 4.7602 | H58: 4.6877 | I58: 5.1972 | J58: 4.8257 | K58: 4.9363 | L58: 5.6703 | M58: 5.8406 | N58: 6.0443 | O58: 6.2168 | P58: 6.2841 | Q58: 6.2913 | R58: 6.3219 | S58: 6.3499 | T58: 6.33 | U58: 6.3691 | V58: 6.453 | W58: 6.5453 | X58: 6.5503 | Y58: 6.5908 | Z58: 6.6735 | AA58: 6.7307 | AB58: 6.697 | AC58: 6.7026 | AD58: ..
A59: Methane (CH4) emissions from Agriculture (Mt CO2e) | B59: EN.GHG.CH4.AG.MT.CE.AR62 | C59: Ecuador | D59: ECU | E59: 9.4341 | F59: 10.4419 | G59: 10.8336 | H59: 11.6926 | I59: 12.4583 | J59: 11.1051 | K59: 11.1528 | L59: 10.805 | M59: 10.8692 | N59: 11.6148 | O59: 11.7374 | P59: 11.7096 | Q59: 11.5625 | R59: 11.5398 | S59: 10.3257 | T59: 9.4576 | U59: 9.3785 | V59: 9.4574 | W59: 8.9401 | X59: 9.2833 | Y59: 9.5339 | Z59: 9.1851 | AA59: 8.7595 | AB59: 8.5377 | AC59: 8.4405 | AD59: ..
A60: Methane (CH4) emissions from Agriculture (Mt CO2e) | B60: EN.GHG.CH4.AG.MT.CE.AR63 | C60: Egypt | D60: EGY | E60: 17.5419 | F60: 17.2445 | G60: 18.9027 | H60: 19.464 | I60: 19.844 | J60: 19.9533 | K60: 20.786 | L60: 22.0464 | M60: 22.7063 | N60: 20.1527 | O60: 19.479 | P60: 21.0202 | Q60: 21.9246 | R60: 21.0114 | S60: 20.8568 | T60: 20.2171 | U60: 20.524 | V60: 19.2057 | W60: 17.3918 | X60: 12.2821 | Y60: 11.7445 | Z60: 11.8957 | AA60: 12.3201 | AB60: 13.8191 | AC60: 13.3955 | AD60: ..
A61: Methane (CH4) emissions from Agriculture (Mt CO2e) | B61: EN.GHG.CH4.AG.MT.CE.AR64 | C61: El Salvador | D61: SLV | E61: 1.884 | F61: 2.1252 | G61: 2.2531 | H61: 2.169 | I61: 2.1941 | J61: 2.185 | K61: 2.2733 | L61: 2.3577 | M61: 2.425 | N61: 2.3313 | O61: 2.1672 | P61: 1.8683 | Q61: 2.0355 | R61: 1.6682 | S61: 1.9599 | T61: 1.9143 | U61: 1.7674 | V61: 1.7004 | W61: 1.5488 | X61: 1.4754 | Y61: 1.5877 | Z61: 1.6517 | AA61: 1.6211 | AB61: 1.5697 | AC61: 1.5704 | AD61: ..
...

Sheet N2O_Em
A1: Series Name | B1: Series Code | C1: Country Name | D1: Country Code | E1: 2000 | F1: 2001 | G1: 2002 | H1: 2003 | I1: 2004 | J1: 2005 | K1: 2006 | L1: 2007 | M1: 2008 | N1: 2009 | O1: 2010 | P1: 2011 | Q1: 2012 | R1: 2013 | S1: 2014 | T1: 2015 | U1: 2016 | V1: 2017 | W1: 2018 | X1: 2019 | Y1: 2020 | Z1: 2021 | AA1: 2022 | AB1: 2023 | AC1: 2024 | AD1: 2025
A2: Nitrous oxide (N2O) emissions from Agriculture (Mt CO2e) | B2: EN.GHG.N2O.AG.MT.CE.AR5 | C2: Afghanistan | D2: AFG | E2: 2.2309 | F2: 1.9857 | G2: 2.3362 | H2: 2.4233 | I2: 2.4067 | J2: 2.5109 | K2: 2.4665 | L2: 2.472 | M2: 2.7046 | N2: 2.8576 | O2: 3.1896 | P2: 3.2347 | Q2: 3.2505 | R2: 3.1859 | S2: 3.3362 | T2: 3.3587 | U2: 3.4896 | V2: 3.9812 | W2: 3.4317 | X2: 3.4545 | Y2: 3.1831 | Z2: 3.0402 | AA2: 3.1185 | AB2: 3.1228 | AC2: 3.137 | AD2: ..
A3: Nitrous oxide (N2O) emissions from Agriculture (Mt CO2e) | B3: EN.GHG.N2O.AG.MT.CE.AR5 | C3: Albania | D3: ALB | E3: 0.7638 | F3: 0.7615 | G3: 0.8149 | H3: 0.7726 | I3: 0.8412 | J3: 0.7159 | K3: 0.7674 | L3: 0.7361 | M3: 0.6821 | N3: 0.6768 | O3: 0.6688 | P3: 0.6852 | Q3: 0.754 | R3: 0.7034 | S3: 0.7701 | T3: 0.7896 | U3: 0.7768 | V3: 0.7586 | W3: 0.7371 | X3: 0.7606 | Y3: 0.6855 | Z3: 0.6575 | AA3: 0.6178 | AB3: 0.5841 | AC3: 0.5545 | AD3: ..
A4: Nitrous oxide (N2O) emissions from Agriculture (Mt CO2e) | B4: EN.GHG.N2O.AG.MT.CE.AR5 | C4: Algeria | D4: DZA | E4: 2.2688 | F4: 2.3033 | G4: 2.26 | H4: 2.3376 | I4: 2.3803 | J4: 2.3881 | K4: 2.4713 | L4: 2.457 | M4: 2.3355 | N4: 2.5978 | O4: 2.8305 | P4: 2.9005 | Q4: 3.0934 | R4: 3.2038 | S4: 3.5552 | T4: 3.658 | U4: 3.5539 | V4: 3.4443 | W4: 3.6594 | X4: 3.6644 | Y4: 3.5199 | Z4: 3.3379 | AA4: 3.5083 | AB4: 3.5923 | AC4: 3.656 | AD4: ..
A5: Nitrous oxide (N2O) emissions from Agriculture (Mt CO2e) | B5: EN.GHG.N2O.AG.MT.CE.AR5 | C5: American Samoa | D5: ASM | E5: 0.0009 | F5: 0.001 | G5: 0.001 | H5: 0.001 | I5: 0.001 | J5: 0.0009 | K5: 0.001 | L5: 0.001 | M5: 0.001 | N5: 0.001 | O5: 0.001 | P5: 0.001 | Q5: 0.001 | R5: 0.001 | S5: 0.001 | T5: 0.001 | U5: 0.001 | V5: 0.001 | W5: 0.001 | X5: 0.001 | Y5: 0.001 | Z5: 0.001 | AA5: 0.001 | AB5: 0.001 | AC5: 0.001 | AD5: ..
A6: Nitrous oxide (N2O) emissions from Agriculture (Mt CO2e) | B6: EN.GHG.N2O.AG.MT.CE.AR5 | C6: Andorra | D6: AND | E6: .. | F6: .. | G6: .. | H6: .. | I6: .. | J6: .. | K6: .. | L6: .. | M6: .. | N6: .. | O6: .. | P6: .. | Q6: .. | R6: .. | S6: .. | T6: .. | U6: .. | V6: .. | W6: .. | X6: .. | Y6: .. | Z6: .. | AA6: .. | AB6: .. | AC6: .. | AD6: ..
A7: Nitrous oxide (N2O) emissions from Agriculture (Mt CO2e) | B7: EN.GHG.N2O.AG.MT.CE.AR5 | C7: Angola | D7: AGO | E7: 2.092 | F7: 2.1067 | G7: 2.1052 | H7: 2.0962 | I7: 2.0785 | J7: 2.2468 | K7: 2.3094 | L7: 2.3913 | M7: 2.4511 | N7: 2.5558 | O7: 2.6525 | P7: 2.7499 | Q7: 2.7954 | R7: 2.9462 | S7: 3.0298 | T7: 3.1374 | U7: 3.1588 | V7: 3.1153 | W7: 3.0985 | X7: 3.2263 | Y7: 3.26 | Z7: 3.322 | AA7: 3.3944 | AB7: 3.3789 | AC7: 3.4219 | AD7: ..
A8: Nitrous oxide (N2O) emissions from Agriculture (Mt CO2e) | B8: EN.GHG.N2O.AG.MT.CE.AR5 | C8: Antigua and Barbuda | D8: ATG | E8: 0.0093 | F8: 0.0096 | G8: 0.0098 | H8: 0.01 | I8: 0.0102 | J8: 0.0102 | K8: 0.0102 | L8: 0.0102 | M8: 0.01 | N8: 0.0099 | O8: 0.0062 | P8: 0.0063 | Q8: 0.0063 | R8: 0.0062 | S8: 0.0063 | T8: 0.0063 | U8: 0.0062 | V8: 0.0063 | W8: 0.006 | X8: 0.0054 | Y8: 0.0052 | Z8: 0.0051 | AA8: 0.005 | AB8: 0.0055 | AC8: 0.0054 | AD8: ..
A9: Nitrous oxide (N2O) emissions from Agriculture (Mt CO2e) | B9: EN.GHG.N2O.AG.MT.CE.AR5 | C9: Argentina | D9: ARG | E9: 25.2087 | F9: 25.8506 | G9: 26.7312 | H9: 28.6076 | I9: 29.6531 | J9: 29.3375 | K9: 30.508 | L9: 31.879 | M9: 30.0032 | N9: 27.6475 | O9: 27.8695 | P9: 28.3535 | Q9: 28.0299 | R9: 29.1033 | S9: 29.681 | T9: 28.8419 | U9: 31.2964 | V9: 32.3089 | W9: 32.5577 | X9: 34.0972 | Y9: 34.6817 | Z9: 34.7446 | AA9: 33.9317 | AB9: 32.7347 | AC9: 33.3887 | AD9: ..
A10: Nitrous oxide (N2O) emissions from Agriculture (Mt CO2e) | B10: EN.GHG.N2O.AG.MT.CE.AR5 | C10: Armenia | D10: ARM | E10: 0.2204 | F10: 0.2224 | G10: 0.2329 | H10: 0.2204 | I10: 0.3078 | J10: 0.2968 | K10: 0.2263 | L10: 0.3253 | M10: 0.2793 | N10: 0.2706 | O10: 0.2535 | P10: 0.2583 | Q10: 0.266 | R10: 0.3116 | S10: 0.3249 | T10: 0.3276 | U10: 0.3443 | V10: 0.3404 | W10: 0.3244 | X10: 0.3439 | Y10: 0.3291 | Z10: 0.3125 | AA10: 0.2993 | AB10: 0.2846 | AC10: 0.2828 | AD10: ..
A11: Nitrous oxide (N2O) emissions from Agriculture (Mt CO2e) | B11: EN.GHG.N2O.AG.MT.CE.AR5 | C11: Aruba | D11: ABW | E11: 0.001 | F11: 0.001 | G11: 0.001 | H11: 0.001 | I11: 0.001 | J11: 0.001 | K11: 0.001 | L11: 0.001 | M11: 0.001 | N11: 0.001 | O11: 0.001 | P11: 0.001 | Q11: 0.001 | R11: 0.001 | S11: 0.001 | T11: 0.001 | U11: 0.001 | V11: 0.001 | W11: 0.001 | X11: 0.001 | Y11: 0.001 | Z11: 0.001 | AA11: 0.001 | AB11: 0.001 | AC11: 0.001 | AD11: ..
A12: Nitrous oxide (N2O) emissions from Agriculture (Mt CO2e) | B12: EN.GHG.N2O.AG.MT.CE.AR5 | C12: Australia | D12: AUS | E12: 34.8807 | F12: 34.762 | G12: 34.4585 | H12: 31.846 | I12: 34.7715 | J12: 34.2219 | K12: 33.2678 | L12: 31.3726 | M12: 30.3615 | N12: 30.8146 | O12: 30.5887 | P12: 32.9616 | Q12: 33.3676 | R12: 34.6795 | S12: 34.9322 | T12: 33.4189 | U12: 32.6106 | V12: 35.8377 | W12: 32.2639 | X12: 30.9473 | Y12: 31.1948 | Z12: 35.425 | AA12: 34.652 | AB12: 37.945 | AC12: 38.6181 | AD12: ..
A13: Nitrous oxide (N2O) emissions from Agriculture (Mt CO2e) | B13: EN.GHG.N2O.AG.MT.CE.AR5 | C13: Austria | D13: AUT | E13: 2.1862 | F13: 2.1918 | G13: 2.101 | H13: 2.0254 | I13: 2.0508 | J13: 2.0502 | K13: 2.0363 | L13: 2.0354 | M13: 1.9961 | N13: 1.9773 | O13: 2.072 | P13: 2.0906 | Q13: 2.0291 | R13: 2.0629 | S13: 2.1524 | T13: 2.1152 | U13: 2.137 | V13: 2.0402 | W13: 2.0012 | X13: 2.0447 | Y13: 2.0369 | Z13: 1.9644 | AA13: 1.9716 | AB13: 1.9626 | AC13: 1.9604 | AD13: ..
A14: Nitrous oxide (N2O) emissions from Agriculture (Mt CO2e) | B14: EN.GHG.N2O.AG.MT.CE.AR5 | C14: Azerbaijan | D14: AZE | E14: 0.9841 | F14: 1.1033 | G14: 1.1939 | H14: 1.286 | I14: 1.2749 | J14: 1.2913 | K14: 1.3558 | L14: 1.3581 | M14: 1.4832 | N14: 1.4818 | O14: 1.4312 | P14: 1.4876 | Q14: 1.5044 | R14: 1.5288 | S14: 1.5985 | T14: 1.6129 | U14: 1.5968 | V14: 1.6468 | W14: 1.6868 | X14: 1.91 | Y14: 1.9106 | Z14: 1.6485 | AA14: 1.9022 | AB14: 1.9023 | AC14: 1.9775 | AD14: ..
